Workbook

Sheet Customer_Dim
A1: Customer_ID | B1: Name | C1: Age | D1: Gender | E1: City | F1: State | G1: Country | H1: Loyalty_Level
A2: CUST1000 | B2: sheena bonilla | C2: 55 | D2: Male | E2: Donaldton | F2: North Carolina | G2: USA
A3: CUST1001 | B3: Eugene Nelson | C3: 26 | D3: Female | E3: Phillipsmouth | F3: North Dakota | G3: USA | H3: Platinum
A4: CUST1002 | B4: dr. Benjamin Price | C4: 29 | D4: Female | E4: Kylebury | F4: Alabama | G4: USA | H4: Platinum
A5: CUST1003 | B5: jeremy harris | C5: 59 | D5: Female | E5: Thomastown | F5: Ohio | G5: USA | H5: Bronze
A6: CUST1004 | B6: Caroline Collins | C6: 64 | D6: Female | E6: Nicholasshire | F6: California | G6: USA | H6: Silver
A7: CUST1005 | B7: Christine Vaughn | C7: 24 | D7: Male | E7: East Amandamouth | F7: Oregon | G7: USA | H7: Bronze
A8: CUST1006 | B8: Amber Jackson | C8: 29 | D8: Female | E8: Deborahborough | F8: South Dakota | G8: USA | H8: Platinum
A9: CUST1007 | B9: Daniel Boyd | C9: 29 | D9: Female | E9: West Pamelafurt | F9: West Virginia | G9: USA | H9: Bronze
A10: CUST1008 | B10: Melissa Howard | C10: 53 | D10: Female | E10: Maynardton | F10: New Hampshire | G10: USA | H10: Gold
A11: CUST1009 | B11: Ms. Maria Leach | C11: 64 | D11: Male | E11: Melissashire | F11: Pennsylvania | G11: USA | H11: Platinum
A12: CUST1010 | B12: Dominic Page | C12: 53 | D12: Male | E12: Port Michaelburgh | F12: Pennsylvania | G12: USA | H12: Bronze
A13: CUST1011 | B13: Brian Lopez | C13: 28 | D13: Female | E13: East Krista | F13: New York | G13: USA | H13: Gold
A14: CUST1012 | B14: Kenneth Lambert | C14: 55 | D14: Female | E14: North Kathryn | F14: Kansas | G14: USA | H14: Platinum
... A19: CUST1017 | B19: Adam Cruz | C19: 60 | D19: Female | E19: Brandonville | F19: Georgia | G19: USA | H19: Platinum
A20: CUST1018 | B20: Rhonda Moss | C20: 43 | D20: Male | E20: South William | F20: Kansas | G20: USA
A21: CUST1019 | B21: Michael Torres | C21: 46 | D21: Female | E21: Gonzalezfort | F21: New Jersey | G21: USA | H21: Platinum
A22: CUST1020 | B22: Bridget Allen | C22: 59 | D22: Male | E22: Lake Shaneburgh | F22: Delaware | G22: USA | H22: Silver
A23: CUST1021 | B23: Jeff Martinez | C23: 36 | D23: Female | E23: Smithburgh | F23: Oklahoma | G23: USA | H23: Gold
A24: CUST1022 | B24: paul fox | C24: 33 | D24: Female | E24: Michaelton | F24: Hawaii | G24: USA | H24: Silver
A25: CUST1023 | B25: Jonathan Steele | C25: 52 | D25: Female | E25: Molinabury | F25: Oregon | G25: USA | H25: Silver
A26: CUST1024 | B26: Heather Collins | C26: 40 | D26: Male | E26: Rogerschester | F26: Idaho | G26: USA | H26: Platinum
A27: CUST1025 | B27: Diana Taylor | C27: 59 | D27: Female | E27: Vasqueztown | F27: California | G27: USA | H27: Bronze
A28: CUST1026 | B28: Amber Carlson | C28: 18 | D28: Female | E28: East Michellemouth | F28: Missouri | G28: USA | H28: Gold
A29: CUST1027 | B29: Leslie Johnson | C29: 31 | D29: Male | E29: Mollyshire | F29: Utah | G29: USA
A30: CUST1028 | B30: Joshua Ryan | C30: 27 | D30: Female | E30: New David | F30: New Jersey | G30: USA | H30: Platinum
A31: CUST1029 | B31: David Arnold | C31: 54 | D31: Female | E31: East Jennifer | F31: California | G31: USA | H31: Silver
A32: CUST1030 | B32: Jessica Acevedo | C32: 64 | D32: Female | E32: Amybury | F32: Pennsylvania | G32: USA | H32: Bronze
A33: CUST1031 | B33: Sarah Vance | C33: 41 | D33: Male | E33: Johnsonville | F33: Oregon | G33: USA | H33: Silver
A34: CUST1032 | B34: Mike Jennings | C34: 48 | D34: Female | E34: Fostermouth | F34: Arizona | G34: USA | H34: Gold
A35: CUST1033 | B35: Robert Jones DDS | C35: 25 | D35: Male | E35: Tristanton | F35: Oklahoma | G35: USA | H35: Platinum
A36: CUST1034 | B36: Christopher Olson | C36: 27 | D36: Female | E36: West Richard | F36: Maryland | G36: USA | H36: Platinum
A37: CUST1035 | B37: Rachel Myers | C37: 52 | D37: Male | E37: Robertberg | F37: North Dakota | G37: USA | H37: Silver
A38: CUST1036 | B38: Thomas Phillips | C38: 20 | D38: Female | E38: Luisfurt | F38: Georgia | G38: USA | H38: Gold
A39: CUST1037 | B39: Christopher Carter | C39: 27 | D39: Female | E39: Brendastad | F39: South Dakota | G39: USA
A40: CUST1038 | B40: Deanna Simpson | C40: 35 | D40: Female | E40: Brownport | F40: North Dakota | G40: USA | H40: Bronze
A41: CUST1039 | B41: Tonya Reynolds | C41: 55 | D41: Female | E41: Darleneton | F41: Michigan | G41: USA | H41: Gold
A42: CUST1040 | B42: Eric Vega | C42: 50 | D42: Male | E42: Williamsonland | F42: Kansas | G42: USA | H42: Gold
A43: CUST1041 | B43: James Gibbs | C43: 21 | D43: Male | E43: Mooneyshire | F43: Alaska | G43: USA | H43: Platinum
A44: CUST1042 | B44: William Martin | C44: 19 | D44: Male | E44: Ryanburgh | F44: Connecticut | G44: USA | H44: Platinum
...

Sheet Product_Dim
A1: Product_ID | B1: Product_Name | C1: Category | D1: Sub_Category | E1: Brand | F1: Cost | G1: Stock
A2: PROD0 | B2: Brother Laser Printer | C2: Electronics | D2: Computer | E2: Hunt Inc | F2: 112.42 | G2: 416
A3: PROD1 | B3: Men's Graphic T-Shirt | C3: Clothing | D3: Tops | E3: Terry-Moore | F3: 342.56 | G3: 181
A4: PROD2 | B4: Women's Casual Hoodie | C4: Clothing | D4: Outerwear | E4: Sims Inc | G4: 352
A5: P-3 | B5: Men's Running Jacket | C5: Clothing | D5: Outerwear | E5: Pineda Ltd | F5: 364.67 | G5: 452
A6: PROD4 | B6: Women's Yoga Pants | C6: Clothing | D6: Bottoms | E6: Gonzales-Davis | F6: 306.46 | G6: 487
A7: PROD5 | B7: Men's Leather Belt | C7: Clothing | D7: Accessories | E7: Baldwin, Garza and Gonzalez | F7: 261 | G7: 59
A8: PROD6 | B8: Herbal Face Moisturizer | C8: Beauty | D8: Skincare | E8: Davidson PLC | F8: 312.8 | G8: 350
A9: PROD7 | B9: LED Table Lamp | C9: Home | D9: Lighting | E9: Harrell LLC | F9: 218.86 | G9: 170
A10: PROD8 | B10: Wireless Bluetooth Earbuds | C10: Electronics | D10: Audio | E10: Perez-Johnston | F10: 439.07 | G10: 142
A11: PROD9 | B11: Adjustable Dumbbell Set | C11: Sports | D11: Fitness | E11: Hill PLC | F11: 495.72 | G11: 323
A12: PROD10 | B12: Ceramic Kitchen Bowl Set | C12: Home | D12: Kitchen | E12: Hamilton Group | F12: 298.86 | G12: 308
A13: PROD11 | B13: HD Smart TV Stick | C13: Electronics | D13: Accessories | E13: Gibson, Hobbs and Weaver | F13: 449.4
A14: PROD12 | B14: Hair Strengthening Shampoo | C14: Beauty | D14: Haircare | E14: Rice LLC | F14: 115.82 | G14: 460
A15: PROD13 | B15: USB-C Fast Charger | C15: Electronics | D15: Accessories | E15: Dawson-Perkins | F15: 242.23 | G15: 453
A16: PROD14 | B16: Decorative Wall Mirror | C16: Home | D16: Decor | E16: Luna, Anderson and Bowman | F16: 48.01 | G16: 439
A17: PROD15 | B17: 4K Home Projector | C17: Electronics | D17: Appliances | E17: Thomas LLC | F17: 465.34 | G17: 301
A18: P-16 | B18: Beard Grooming Kit | C18: Beauty | D18: Grooming | E18: Erickson-Green | F18: 337.42 | G18: 256
A19: PROD17 | B19: Soccer Training Cone Set | C19: Sports | D19: Accessories | E19: Ford, Murphy and Wilson | F19: 144.53 | G19: 367
A20: PROD18 | B20: Women's Denim Jeans | C20: Clothing | D20: Bottoms | E20: Guerra-Hendrix | G20: 343
A21: PROD19 | B21: Knee Support Brace | C21: Sports | D21: Equipment | E21: May-Reese | F21: 21.34 | G21: 65
A22: PROD20 | B22: Outdoor Sports Water Bottle | C22: Sports | D22: Accessories | E22: Soto-Ellis | F22: 131.51
A23: PROD21 | B23: Multi-Purpose Storage Box | C23: Home | D23: Storage | E23: Gardner-Montes | F23: 123.46 | G23: 76
A24: PROD22 | B24: Carbon Fiber Tennis Racket | C24: Sports | D24: Equipment | E24: Flores, Pineda and Rodriguez | F24: 484.62 | G24: 432
A25: PROD23 | B25: Men's Formal Shirt | C25: Clothing | D25: Tops | E25: Moon, Mora and Santos | G25: 360
A26: PROD24 | B26: Foldable Camping Chair | C26: Sports | D26: Outdoor | E26: Cook Ltd | F26: 166.06 | G26: 340
A27: PROD25 | B27: Women's Scarf Set | C27: Clothing | D27: Accessories | E27: Brown and Sons | F27: 174.02 | G27: 268
A28: PROD26 | B28: Wireless Bluetooth Speaker | C28: Electronics | D28: Audio | E28: Reed-Schmidt | F28: 322.41 | G28: 213
A29: PROD27 | B29: Decorative Floor Vase | C29: Home | D29: Decor | E29: Khan, Jones and Paul | G29: 378
A30: PROD28 | B30: Sports Stopwatch Timer | C30: Sports | D30: Accessories | E30: Burns-Hansen | F30: 38.76 | G30: 137
A31: PROD29 | B31: Fabric Sofa Throw Blanket | C31: Home | D31: Decor | E31: Hoffman Group | F31: 218.48 | G31: 276
A32: PROD30 | B32: Stainless Steel Cutlery Set | C32: Home | D32: Kitchen | E32: Stevens, Fernandez and Martin | F32: 19.52 | G32: 57
A33: PROD31 | B33: Basketball | C33: Sports | D33: Team Sports | E33: Nolan-Snow | F33: 204.39 | G33: 281
A34: PROD32 | B34: Vitamin C Face Serum | C34: Beauty | D34: Skincare | E34: Griffin Ltd | F34: 283.83 | G34: 244
A35: PROD33 | B35: Modern Wall Clock | C35: Home | D35: Decor | E35: Weiss-Watson | F35: 179.77 | G35: 305
A36: PROD34 | B36: Gaming Mechanical Keyboard | C36: Electronics | D36: Computer | E36: Lucero LLC | F36: 419.28 | G36: 86
A37: PROD35 | B37: Bedroom Table Lamp | C37: Home | D37: Lighting | E37: Jones LLC | F37: 382.22 | G37: 329
A38: PROD36 | B38: Women's Summer Dress | C38: Clothing | D38: Tops | E38: Smith-Mills | F38: 223.43 | G38: 154
A39: PROD37 | B39: Men's Casual Sneakers | C39: Clothing | D39: Footwear | E39: Hogan-Lee | F39: 353.47 | G39: 214
A40: PROD38 | B40: Sports Water Hydration Pack | C40: Sports | D40: Outdoor | E40: Sims-Smith | F40: 135.61 | G40: 394
...

Sheet Store_Dim
A1: Store_ID | B1: Store_Name | C1: Region | D1: City | E1: Store_Type
A2: STORE0 | B2: Rivera-Warner | C2: East | D2: Washingtonfurt | E2: Flagship
A3: STORE1 | B3: Martinez, Adkins and Johnson | C3: North | D3: Danielmouth | E3: Flagship
A4: STORE2 | B4: Black-Horn | C4: South | D4: North Nancyview | E4: Outlet
A5: STORE3 | B5: Johnson-Wright | C5: North | D5: Hoodberg | E5: Outlet
A6: STORE4 | B6: Alexander Group | C6: South | D6: Port Sharon | E6: Online
A7: STORE5 | B7: Gray Ltd | C7: North | D7: New Michaelchester | E7: Outlet
A8: STORE6 | B8: Benson-Elliott | C8: East | D8: Port Josephberg | E8: Online
A9: STORE7 | B9: Martinez-Mullins | C9: South | D9: Williamsfurt | E9: Online
A10: STORE8 | B10: Bean, Jones and Park | C10: West | D10: Thompsonborough | E10: Online
A11: STORE9 | B11: Moore, Padilla and Butler | C11: South | D11: East Johnstad | E11: Flagship
A12: STORE10 | B12: Hill, Wagner and Ballard | C12: East | D12: East Davidville | E12: Online
... A21: STORE19 | B21: Mann-Austin | C21: East | D21: Vasquezborough | E21: Online

Sheet Sales_Fact
A1: Sales_ID | B1: Order_Date | C1: Customer_ID | D1: Product_ID | E1: Store_ID | F1: Quantity | G1: Unit_Price | H1: Discount | I1: Payment_Type | J1: Total_Amount
A2: SALE0 | B2: 45480 | C2: CUST1409 | D2: PROD97 | E2: STORE3 | F2: 1 | G2: 218.04 | H2: 0.09 | I2: Credit Card | J2: 198.4164
A3: SALE1 | B3: 45285 | C3: CUST1467 | D3: PROD74 | E3: STORE17 | F3: 3 | G3: 104.47 | H3: 0.27 | I3: PayPal | J3: 228.7893
A4: SALE2 | B4: 45446 | C4: CUST1056 | D4: PROD49 | E4: STORE8 | F4: 4 | G4: 914.05 | H4: 0.25 | I4: Credit Card | J4: 2742.15
A5: SALE3 | B5: 45259 | C5: CUST1346 | D5: PROD76 | E5: STORE8 | F5: 1 | G5: 921.51 | H5: 0.16 | I5: COD | J5: 774.0684
A6: SALE4 | B6: 45297 | C6: CUST1493 | D6: PROD59 | E6: STORE5 | F6: 3 | G6: 745.3 | H6: 0.18 | I6: Credit Card | J6: 1833.438
A7: SALE5 | B7: 45499 | C7: CUST1116 | D7: PROD15 | E7: STORE7 | F7: 3 | G7: 147.01 | H7: 0.19 | I7: COD | J7: 357.2343
A8: SALE6 | B8: 45850 | C8: CUST1016 | D8: PROD56 | E8: STORE4 | F8: 2 | G8: 785.31 | H8: 0.15 | I8: PayPal | J8: 1335.027
A9: SALE7 | B9: 45248 | C9: CUST1152 | D9: PROD70 | E9: STORE8 | F9: 4 | G9: 342.39 | H9: 0.23 | I9: PayPal | J9: 1054.5612
A10: SALE8 | B10: 45781 | C10: CUST1187 | D10: PROD99 | E10: STORE5 | G10: 448.25 | H10: 0.07 | I10: PayPal | J10: 1250.6175
A11: SALE9 | B11: 45869 | C11: CUST1464 | D11: PROD33 | E11: STORE0 | F11: 2 | G11: 873.17 | H11: 0.23 | I11: PayPal | J11: 1344.6818
A12: SALE10 | B12: 45335 | C12: CUST1065 | D12: PROD24 | E12: STORE14 | F12: 1 | G12: 278.63 | H12: 0.07 | I12: Credit Card | J12: 259.1259
A13: SALE11 | B13: 45801 | C13: CUST1320 | D13: PROD39 | E13: STORE1 | F13: 4 | G13: 286.92 | H13: 0.17 | I13: Credit Card | J13: 952.5744
A14: SALE12 | B14: 45528 | C14: CUST1237 | D14: PROD88 | E14: STORE4 | F14: 4 | G14: 644.58 | H14: 0.01 | I14: Credit Card | J14: 2552.5368
A15: SALE13 | B15: 45875 | C15: CUST1443 | D15: PROD34 | E15: STORE16 | F15: 2 | G15: 316.9 | H15: 0.3 | I15: PayPal | J15: 443.66
A16: SALE14 | B16: 45829 | C16: CUST1348 | D16: PROD24 | E16: STORE15 | F16: 4 | G16: 403.47 | H16: 0.29 | I16: PayPal | J16: 1145.8548
A17: SALE15 | B17: 45636 | C17: CUST1435 | D17: PROD36 | E17: STORE9 | G17: 871.34 | H17: 0.04 | I17: COD | J17: 2509.4592
A18: SALE16 | B18: 45913 | C18: CUST1276 | D18: PROD65 | E18: STORE19 | F18: 2 | G18: 451.98 | H18: 0.25 | I18: Credit Card | J18: 677.97
A19: SALE17 | B19: 45637 | C19: CUST1079 | D19: PROD27 | E19: STORE4 | F19: 2 | G19: 502.69 | H19: 0.23 | I19: Credit Card | J19: 774.1426
A20: SALE18 | B20: 45517 | C20: CUST1094 | D20: PROD39 | E20: STORE4 | F20: 2 | G20: 559.23 | H20: 0.25 | I20: COD | J20: 838.845
A21: SALE19 | B21: 45369 | C21: CUST1239 | D21: PROD60 | E21: STORE13 | F21: 4 | H21: 0.04 | I21: COD | J21: 1782.4512
A22: SALE20 | B22: 45843 | C22: CUST1144 | D22: PROD72 | E22: STORE17 | F22: 3 | G22: 986.04 | H22: 0.27 | I22: COD | J22: 2159.4276
A23: SALE21 | B23: 45447 | C23: CUST1396 | D23: PROD43 | E23: STORE18 | F23: 1 | G23: 589.56 | H23: 0.22 | I23: Credit Card | J23: 459.8568
A24: SALE22 | B24: 45394 | C24: CUST1476 | D24: PROD69 | E24: STORE10 | F24: 3 | G24: 979.42 | H24: 0.03 | I24: PayPal | J24: 2850.1122
A25: SALE23 | B25: 45466 | C25: CUST1368 | D25: PROD12 | E25: STORE8 | F25: 1 | G25: 719.28 | H25: 0.08 | I25: Credit Card | J25: 661.7376
A26: SALE24 | B26: 45908 | C26: CUST1186 | D26: PROD67 | E26: STORE6 | F26: 3 | G26: 77.6 | H26: 0.07 | I26: Credit Card | J26: 216.504
A27: SALE25 | B27: 45552 | C27: CUST1381 | D27: PROD5 | E27: STORE3 | F27: 4 | G27: 852.71 | H27: 0.14 | I27: PayPal | J27: 2933.3224
A28: SALE26 | B28: 45294 | C28: CUST1213 | D28: PROD98 | E28: STORE8 | F28: 4 | G28: 156.16 | I28: Credit Card | J28: 599.6544
A29: SALE27 | B29: 45710 | C29: CUST1200 | D29: PROD77 | E29: STORE8 | F29: 3 | G29: 815.49 | H29: 0.17 | I29: Credit Card | J29: 2030.5701
A30: SALE28 | B30: 45923 | C30: CUST1148 | D30: PROD13 | E30: STORE2 | F30: 2 | G30: 74.21 | H30: 0.11 | I30: PayPal | J30: 132.0938
A31: SALE29 | B31: 45302 | C31: CUST1348 | D31: PROD99 | E31: STORE3 | G31: 451.67 | H31: 0.15 | I31: Credit Card | J31: 1535.678
A32: SALE30 | B32: 45217 | C32: CUST1028 | D32: PROD5 | E32: STORE19 | F32: 1 | G32: 429.38 | H32: 0.13 | I32: PayPal | J32: 373.5606
A33: SALE31 | B33: 45593 | C33: CUST1412 | D33: PROD53 | E33: STORE12 | F33: 2 | G33: 148.96 | H33: 0.03 | I33: COD | J33: 288.9824
A34: SALE32 | B34: 45597 | C34: CUST1398 | D34: PROD75 | E34: STORE8 | F34: 4 | G34: 313.83 | H34: 0.08 | I34: Credit Card | J34: 1154.8944
A35: SALE33 | B35: 45620 | C35: CUST1453 | D35: PROD12 | E35: STORE6 | F35: 2 | G35: 717.31 | H35: 0.15 | I35: Credit Card | J35: 1219.427
A36: SALE34 | B36: 45215 | C36: CUST1344 | D36: PROD79 | E36: STORE1 | G36: 873.22 | H36: 0.18 | I36: Credit Card | J36: 2148.1212
A37: SALE35 | B37: 45878 | C37: CUST1218 | D37: PROD16 | E37: STORE3 | F37: 4 | G37: 109.36 | H37: 0.19 | I37: COD | J37: 354.3264
A38: SALE36 | B38: 45635 | C38: CUST1086 | D38: PROD5 | E38: STORE7 | F38: 3 | G38: 559.52 | H38: 0.16 | I38: PayPal | J38: 1409.9904
A39: SALE37 | B39: 45329 | C39: CUST1492 | D39: PROD10 | E39: STORE17 | F39: 3 | G39: 121.76 | H39: 0.27 | I39: PayPal | J39: 266.6544
A40: SALE38 | B40: 45378 | C40: CUST1189 | D40: PROD33 | E40: STORE13 | F40: 4 | G40: 735.32 | H40: 0.06 | I40: COD | J40: 2764.8032
...

Sheet Observations
A2: Table/Sheet | B2: Observations | C2: Transformation Applied
A3: Customer_Dim/Product_Dim/Store_Dim/Sales_Fact | B3: Dataset
A4: Customer | B4: Some Customer Id was not in proper Formet | C4: Replaced CUST for C-
B5: Name Column was not in proper formet | C5: Used Captalized Each word using Power query
B6: Some datas spelled wrongly in Country Column | C6: Replaced with correct data
B7: Some Loyalty levels are blank | C7: Replaced blanks with unknown
B8: Descriptive Statistics | C8: Descriptive Statistics was applied using Analysys ToolPak
B9: Customer level Column added | C9: Customer level Column added using IFS condition
A10: Product | B10: Some Product Id was not in proper Formet | C10: Replaced PROD for P-
B11: Missing Datas in Cost and Stock Column | C11: Filled by calculating Average using Power query
B12: Descriptive Statistics | C12: Descriptive Statistics was applied using Analysys ToolPak
B13: Product Name Colum Splitted | C13: Product Name Colum Splitted into Description and type
A14: Store | B14: Store Category Column added | C14: Store Category Column added with IF Condition
A15: Sales | B15: Missing Datas in Total Amount Column | C15: Filled by using formula by creating a new column Amount Paid
B16: Descriptive Statistics | C16: Descriptive Statistics was applied using Analysys ToolPak
B17: Price Range Column added | C17: Price Range Column added using IFS Condition
A18: VLOOKUP | C18: Merged all 4 Tables using VLOOKUP
A19: PIVOT_LOOKUP PIVOT_LOOKUP2 | C19: Used Pivot Table for creating Charts from the VLOOKUP Sheet
A20: PIVOT TABLE_PRODUCT,STORE | C20: Used Pivot Table for creating Charts from Product and Store table
A21: PIVOT TABLE_CUST | C21: Used Pivot Table for creating Charts from Customer Table
A22: DASHBOARD | C22: All the Pivot Charts are pasted here to form a dashboard

Sheet DASHBOARD

Sheet Customer
A1: Customer_ID | B1: Name | C1: Age | D1: Gender | E1: City | F1: State | G1: Country | H1: Loyalty_Level | M1: Customer_ID | N1: Name | O1: Age | P1: Gender | Q1: City | R1: State | S1: Country | T1: Loyalty_Level | U1: Customer Level
A2: CUST1000 | B2: sheena bonilla | C2: 55 | D2: Male | E2: Donaldton | F2: North Carolina | G2: USA | M2: CUST1000 | N2: Sheena Bonilla | O2: 55 | P2: Male | Q2: Donaldton | R2: North Carolina | S2: USA | T2: unknown | U2: =_xlfn.IFS(Table1__2[[#This Row],[Age]]<=19,"Teenage",Table1__2[[#This Row],[Age]]<=24,"Students",Table1__2[[#This Row],[Age]]<=30,"Entry level Professionel",Table1__2[[#This Row],[Age]]<=60,"Experienced",Table1__2[[#This Row],[Age]]>60,"Retired") -> Experienced
A3: CUST1001 | B3: Eugene Nelson | C3: 26 | D3: Female | E3: Phillipsmouth | F3: North Dakota | G3: USA | H3: Platinum | M3: CUST1001 | N3: Eugene Nelson | O3: 26 | P3: Female | Q3: Phillipsmouth | R3: North Dakota | S3: USA | T3: Platinum | U3: =_xlfn.IFS(Table1__2[[#This Row],[Age]]<=19,"Teenage",Table1__2[[#This Row],[Age]]<=24,"Students",Table1__2[[#This Row],[Age]]<=30,"Entry level Professionel",Table1__2[[#This Row],[Age]]<=60,"Experienced",Table1__2[[#This Row],[Age]]>60,"Retired") -> Entry level Professionel | W3: Descriptive Statistics
A4: CUST1002 | B4: dr. Benjamin Price | C4: 29 | D4: Female | E4: Kylebury | F4: Alabama | G4: USA | H4: Platinum | M4: CUST1002 | N4: Dr. Benjamin Price | O4: 29 | P4: Female | Q4: Kylebury | R4: Alabama | S4: USA | T4: Platinum | U4: =_xlfn.IFS(Table1__2[[#This Row],[Age]]<=19,"Teenage",Table1__2[[#This Row],[Age]]<=24,"Students",Table1__2[[#This Row],[Age]]<=30,"Entry level Professionel",Table1__2[[#This Row],[Age]]<=60,"Experienced",Table1__2[[#This Row],[Age]]>60,"Retired") -> Entry level Professionel | W4: Age
A5: CUST1003 | B5: jeremy harris | C5: 59 | D5: Female | E5: Thomastown | F5: Ohio | G5: USA | H5: Bronze | M5: CUST1003 | N5: Jeremy Harris | O5: 59 | P5: Female | Q5: Thomastown | R5: Ohio | S5: USA | T5: Bronze | U5: =_xlfn.IFS(Table1__2[[#This Row],[Age]]<=19,"Teenage",Table1__2[[#This Row],[Age]]<=24,"Students",Table1__2[[#This Row],[Age]]<=30,"Entry level Professionel",Table1__2[[#This Row],[Age]]<=60,"Experienced",Table1__2[[#This Row],[Age]]>60,"Retired") -> Experienced
A6: CUST1004 | B6: Caroline Collins | C6: 64 | D6: Female | E6: Nicholasshire | F6: California | G6: USA | H6: Silver | M6: CUST1004 | N6: Caroline Collins | O6: 64 | P6: Female | Q6: Nicholasshire | R6: California | S6: USA | T6: Silver | U6: =_xlfn.IFS(Table1__2[[#This Row],[Age]]<=19,"Teenage",Table1__2[[#This Row],[Age]]<=24,"Students",Table1__2[[#This Row],[Age]]<=30,"Entry level Professionel",Table1__2[[#This Row],[Age]]<=60,"Experienced",Table1__2[[#This Row],[Age]]>60,"Retired") -> Retired | W6: Mean | X6: 41.562
A7: CUST1005 | B7: Christine Vaughn | C7: 24 | D7: Male | E7: East Amandamouth | F7: Oregon | G7: USA | H7: Bronze | M7: CUST1005 | N7: Christine Vaughn | O7: 24 | P7: Male | Q7: East Amandamouth | R7: Oregon | S7: USA | T7: Bronze | U7: =_xlfn.IFS(Table1__2[[#This Row],[Age]]<=19,"Teenage",Table1__2[[#This Row],[Age]]<=24,"Students",Table1__2[[#This Row],[Age]]<=30,"Entry level Professionel",Table1__2[[#This Row],[Age]]<=60,"Experienced",Table1__2[[#This Row],[Age]]>60,"Retired") -> Students | W7: Standard Error | X7: 0.61138523
A8: CUST1006 | B8: Amber Jackson | C8: 29 | D8: Female | E8: Deborahborough | F8: South Dakota | G8: USA | H8: Platinum | M8: CUST1006 | N8: Amber Jackson | O8: 29 | P8: Female | Q8: Deborahborough | R8: South Dakota | S8: USA | T8: Platinum | U8: =_xlfn.IFS(Table1__2[[#This Row],[Age]]<=19,"Teenage",Table1__2[[#This Row],[Age]]<=24,"Students",Table1__2[[#This Row],[Age]]<=30,"Entry level Professionel",Table1__2[[#This Row],[Age]]<=60,"Experienced",Table1__2[[#This Row],[Age]]>60,"Retired") -> Entry level Professionel | W8: Median | X8: 42
A9: CUST1007 | B9: Daniel Boyd | C9: 29 | D9: Female | E9: West Pamelafurt | F9: West Virginia | G9: USA | H9: Bronze | M9: CUST1007 | N9: Daniel Boyd | O9: 29 | P9: Female | Q9: West Pamelafurt | R9: West Virginia | S9: USA | T9: Bronze | U9: =_xlfn.IFS(Table1__2[[#This Row],[Age]]<=19,"Teenage",Table1__2[[#This Row],[Age]]<=24,"Students",Table1__2[[#This Row],[Age]]<=30,"Entry level Professionel",Table1__2[[#This Row],[Age]]<=60,"Experienced",Table1__2[[#This Row],[Age]]>60,"Retired") -> Entry level Professionel | W9: Mode | X9: 46
A10: CUST1008 | B10: Melissa Howard | C10: 53 | D10: Female | E10: Maynardton | F10: New Hampshire | G10: USA | H10: Gold | M10: CUST1008 | N10: Melissa Howard | O10: 53 | P10: Female | Q10: Maynardton | R10: New Hampshire | S10: USA | T10: Gold | U10: =_xlfn.IFS(Table1__2[[#This Row],[Age]]<=19,"Teenage",Table1__2[[#This Row],[Age]]<=24,"Students",Table1__2[[#This Row],[Age]]<=30,"Entry level Professionel",Table1__2[[#This Row],[Age]]<=60,"Experienced",Table1__2[[#This Row],[Age]]>60,"Retired") -> Experienced | W10: Standard Deviation | X10: 13.670989
A11: CUST1009 | B11: Ms. Maria Leach | C11: 64 | D11: Male | E11: Melissashire | F11: Pennsylvania | G11: USA | H11: Platinum | M11: CUST1009 | N11: Ms. Maria Leach | O11: 64 | P11: Male | Q11: Melissashire | R11: Pennsylvania | S11: USA | T11: Platinum | U11: =_xlfn.IFS(Table1__2[[#This Row],[Age]]<=19,"Teenage",Table1__2[[#This Row],[Age]]<=24,"Students",Table1__2[[#This Row],[Age]]<=30,"Entry level Professionel",Table1__2[[#This Row],[Age]]<=60,"Experienced",Table1__2[[#This Row],[Age]]>60,"Retired") -> Retired | W11: Sample Variance | X11: 186.89595
A12: CUST1010 | B12: Dominic Page | C12: 53 | D12: Male | E12: Port Michaelburgh | F12: Pennsylvania | G12: USA | H12: Bronze | M12: CUST1010 | N12: Dominic Page | O12: 53 | P12: Male | Q12: Port Michaelburgh | R12: Pennsylvania | S12: USA | T12: Bronze | U12: =_xlfn.IFS(Table1__2[[#This Row],[Age]]<=19,"Teenage",Table1__2[[#This Row],[Age]]<=24,"Students",Table1__2[[#This Row],[Age]]<=30,"Entry level Professionel",Table1__2[[#This Row],[Age]]<=60,"Experienced",Table1__2[[#This Row],[Age]]>60,"Retired") -> Experienced | W12: Kurtosis | X12: -1.219392
A13: CUST1011 | B13: Brian Lopez | C13: 28 | D13: Female | E13: East Krista | F13: New York | G13: USA | H13: Gold | M13: CUST1011 | N13: Brian Lopez | O13: 28 | P13: Female | Q13: East Krista | R13: New York | S13: USA | T13: Gold | U13: =_xlfn.IFS(Table1__2[[#This Row],[Age]]<=19,"Teenage",Table1__2[[#This Row],[Age]]<=24,"Students",Table1__2[[#This Row],[Age]]<=30,"Entry level Professionel",Table1__2[[#This Row],[Age]]<=60,"Experienced",Table1__2[[#This Row],[Age]]>60,"Retired") -> Entry level Professionel | W13: Skewness | X13: -0.03654853
A14: CUST1012 | B14: Kenneth Lambert | C14: 55 | D14: Female | E14: North Kathryn | F14: Kansas | G14: USA | H14: Platinum | M14: CUST1012 | N14: Kenneth Lambert | O14: 55 | P14: Female | Q14: North Kathryn | R14: Kansas | S14: USA | T14: Platinum | U14: =_xlfn.IFS(Table1__2[[#This Row],[Age]]<=19,"Teenage",Table1__2[[#This Row],[Age]]<=24,"Students",Table1__2[[#This Row],[Age]]<=30,"Entry level Professionel",Table1__2[[#This Row],[Age]]<=60,"Experienced",Table1__2[[#This Row],[Age]]>60,"Retired") -> Experienced | W14: Range | X14: 46
A15: CUST1013 | B15: Nathan Hernandez | C15: 32 | D15: Female | E15: New Becky | F15: Montana | G15: USA | H15: Silver | M15: CUST1013 | N15: Nathan Hernandez | O15: 32 | P15: Female | Q15: New Becky | R15: Montana | S15: USA | T15: Silver | U15: =_xlfn.IFS(Table1__2[[#This Row],[Age]]<=19,"Teenage",Table1__2[[#This Row],[Age]]<=24,"Students",Table1__2[[#This Row],[Age]]<=30,"Entry level Professionel",Table1__2[[#This Row],[Age]]<=60,"Experienced",Table1__2[[#This Row],[Age]]>60,"Retired") -> Experienced | W15: Minimum | X15: 18
A16: CUST1014 | B16: Ashley Cohen | C16: 53 | D16: Female | E16: Lake Kristamouth | F16: Nebraska | G16: USA | H16: Silver | M16: CUST1014 | N16: Ashley Cohen | O16: 53 | P16: Female | Q16: Lake Kristamouth | R16: Nebraska | S16: USA | T16: Silver | U16: =_xlfn.IFS(Table1__2[[#This Row],[Age]]<=19,"Teenage",Table1__2[[#This Row],[Age]]<=24,"Students",Table1__2[[#This Row],[Age]]<=30,"Entry level Professionel",Table1__2[[#This Row],[Age]]<=60,"Experienced",Table1__2[[#This Row],[Age]]>60,"Retired") -> Experienced | W16: Maximum | X16: 64
A17: CUST1015 | B17: Laura Alvarez | C17: 49 | D17: Female | E17: Lawsonhaven | F17: Washington | G17: USA | H17: Platinum | M17: CUST1015 | N17: Laura Alvarez | O17: 49 | P17: Female | Q17: Lawsonhaven | R17: Washington | S17: USA | T17: Platinum | U17: =_xlfn.IFS(Table1__2[[#This Row],[Age]]<=19,"Teenage",Table1__2[[#This Row],[Age]]<=24,"Students",Table1__2[[#This Row],[Age]]<=30,"Entry level Professionel",Table1__2[[#This Row],[Age]]<=60,"Experienced",Table1__2[[#This Row],[Age]]>60,"Retired") -> Experienced | W17: Sum | X17: 20781
A18: CUST1016 | B18: John Scott | C18: 24 | D18: Female | E18: South Christopher | F18: Pennsylvania | G18: USA | H18: Bronze | M18: CUST1016 | N18: John Scott | O18: 24 | P18: Female | Q18: South Christopher | R18: Pennsylvania | S18: USA | T18: Bronze | U18: =_xlfn.IFS(Table1__2[[#This Row],[Age]]<=19,"Teenage",Table1__2[[#This Row],[Age]]<=24,"Students",Table1__2[[#This Row],[Age]]<=30,"Entry level Professionel",Table1__2[[#This Row],[Age]]<=60,"Experienced",Table1__2[[#This Row],[Age]]>60,"Retired") -> Students | W18: Count | X18: 500
A19: CUST1017 | B19: Adam Cruz | C19: 60 | D19: Female | E19: Brandonville | F19: Georgia | G19: USA | H19: Platinum | M19: CUST1017 | N19: Adam Cruz | O19: 60 | P19: Female | Q19: Brandonville | R19: Georgia | S19: USA | T19: Platinum | U19: =_xlfn.IFS(Table1__2[[#This Row],[Age]]<=19,"Teenage",Table1__2[[#This Row],[Age]]<=24,"Students",Table1__2[[#This Row],[Age]]<=30,"Entry level Professionel",Table1__2[[#This Row],[Age]]<=60,"Experienced",Table1__2[[#This Row],[Age]]>60,"Retired") -> Experienced
A20: CUST1018 | B20: Rhonda Moss | C20: 43 | D20: Male | E20: South William | F20: Kansas | G20: USA | M20: CUST1018 | N20: Rhonda Moss | O20: 43 | P20: Male | Q20: South William | R20: Kansas | S20: USA | T20: unknown | U20: =_xlfn.IFS(Table1__2[[#This Row],[Age]]<=19,"Teenage",Table1__2[[#This Row],[Age]]<=24,"Students",Table1__2[[#This Row],[Age]]<=30,"Entry level Professionel",Table1__2[[#This Row],[Age]]<=60,"Experienced",Table1__2[[#This Row],[Age]]>60,"Retired") -> Experienced
A21: CUST1019 | B21: Michael Torres | C21: 46 | D21: Female | E21: Gonzalezfort | F21: New Jersey | G21: USA | H21: Platinum | M21: CUST1019 | N21: Michael Torres | O21: 46 | P21: Female | Q21: Gonzalezfort | R21: New Jersey | S21: USA | T21: Platinum | U21: =_xlfn.IFS(Table1__2[[#This Row],[Age]]<=19,"Teenage",Table1__2[[#This Row],[Age]]<=24,"Students",Table1__2[[#This Row],[Age]]<=30,"Entry level Professionel",Table1__2[[#This Row],[Age]]<=60,"Experienced",Table1__2[[#This Row],[Age]]>60,"Retired") -> Experienced
A22: CUST1020 | B22: Bridget Allen | C22: 59 | D22: Male | E22: Lake Shaneburgh | F22: Delaware | G22: USA | H22: Silver | M22: CUST1020 | N22: Bridget Allen | O22: 59 | P22: Male | Q22: Lake Shaneburgh | R22: Delaware | S22: USA | T22: Silver | U22: =_xlfn.IFS(Table1__2[[#This Row],[Age]]<=19,"Teenage",Table1__2[[#This Row],[Age]]<=24,"Students",Table1__2[[#This Row],[Age]]<=30,"Entry level Professionel",Table1__2[[#This Row],[Age]]<=60,"Experienced",Table1__2[[#This Row],[Age]]>60,"Retired") -> Experienced
A23: CUST1021 | B23: Jeff Martinez | C23: 36 | D23: Female | E23: Smithburgh | F23: Oklahoma | G23: USA | H23: Gold | M23: CUST1021 | N23: Jeff Martinez | O23: 36 | P23: Female | Q23: Smithburgh | R23: Oklahoma | S23: USA | T23: Gold | U23: =_xlfn.IFS(Table1__2[[#This Row],[Age]]<=19,"Teenage",Table1__2[[#This Row],[Age]]<=24,"Students",Table1__2[[#This Row],[Age]]<=30,"Entry level Professionel",Table1__2[[#This Row],[Age]]<=60,"Experienced",Table1__2[[#This Row],[Age]]>60,"Retired") -> Experienced
A24: CUST1022 | B24: paul fox | C24: 33 | D24: Female | E24: Michaelton | F24: Hawaii | G24: USA | H24: Silver | M24: CUST1022 | N24: Paul Fox | O24: 33 | P24: Female | Q24: Michaelton | R24: Hawaii | S24: USA | T24: Silver | U24: =_xlfn.IFS(Table1__2[[#This Row],[Age]]<=19,"Teenage",Table1__2[[#This Row],[Age]]<=24,"Students",Table1__2[[#This Row],[Age]]<=30,"Entry level Professionel",Table1__2[[#This Row],[Age]]<=60,"Experienced",Table1__2[[#This Row],[Age]]>60,"Retired") -> Experienced
A25: CUST1023 | B25: Jonathan Steele | C25: 52 | D25: Female | E25: Molinabury | F25: Oregon | G25: USA | H25: Silver | M25: CUST1023 | N25: Jonathan Steele | O25: 52 | P25: Female | Q25: Molinabury | R25: Oregon | S25: USA | T25: Silver | U25: =_xlfn.IFS(Table1__2[[#This Row],[Age]]<=19,"Teenage",Table1__2[[#This Row],[Age]]<=24,"Students",Table1__2[[#This Row],[Age]]<=30,"Entry level Professionel",Table1__2[[#This Row],[Age]]<=60,"Experienced",Table1__2[[#This Row],[Age]]>60,"Retired") -> Experienced
A26: CUST1024 | B26: Heather Collins | C26: 40 | D26: Male | E26: Rogerschester | F26: Idaho | G26: USA | H26: Platinum | M26: CUST1024 | N26: Heather Collins | O26: 40 | P26: Male | Q26: Rogerschester | R26: Idaho | S26: USA | T26: Platinum | U26: =_xlfn.IFS(Table1__2[[#This Row],[Age]]<=19,"Teenage",Table1__2[[#This Row],[Age]]<=24,"Students",Table1__2[[#This Row],[Age]]<=30,"Entry level Professionel",Table1__2[[#This Row],[Age]]<=60,"Experienced",Table1__2[[#This Row],[Age]]>60,"Retired") -> Experienced
A27: CUST1025 | B27: Diana Taylor | C27: 59 | D27: Female | E27: Vasqueztown | F27: California | G27: USA | H27: Bronze | M27: CUST1025 | N27: Diana Taylor | O27: 59 | P27: Female | Q27: Vasqueztown | R27: California | S27: USA | T27: Bronze | U27: =_xlfn.IFS(Table1__2[[#This Row],[Age]]<=19,"Teenage",Table1__2[[#This Row],[Age]]<=24,"Students",Table1__2[[#This Row],[Age]]<=30,"Entry level Professionel",Table1__2[[#This Row],[Age]]<=60,"Experienced",Table1__2[[#This Row],[Age]]>60,"Retired") -> Experienced
A28: CUST1026 | B28: Amber Carlson | C28: 18 | D28: Female | E28: East Michellemouth | F28: Missouri | G28: USA | H28: Gold | M28: CUST1026 | N28: Amber Carlson | O28: 18 | P28: Female | Q28: East Michellemouth | R28: Missouri | S28: USA | T28: Gold | U28: =_xlfn.IFS(Table1__2[[#This Row],[Age]]<=19,"Teenage",Table1__2[[#This Row],[Age]]<=24,"Students",Table1__2[[#This Row],[Age]]<=30,"Entry level Professionel",Table1__2[[#This Row],[Age]]<=60,"Experienced",Table1__2[[#This Row],[Age]]>60,"Retired") -> Teenage
A29: CUST1027 | B29: Leslie Johnson | C29: 31 | D29: Male | E29: Mollyshire | F29: Utah | G29: USA | M29: CUST1027 | N29: Leslie Johnson | O29: 31 | P29: Male | Q29: Mollyshire | R29: Utah | S29: USA | T29: unknown | U29: =_xlfn.IFS(Table1__2[[#This Row],[Age]]<=19,"Teenage",Table1__2[[#This Row],[Age]]<=24,"Students",Table1__2[[#This Row],[Age]]<=30,"Entry level Professionel",Table1__2[[#This Row],[Age]]<=60,"Experienced",Table1__2[[#This Row],[Age]]>60,"Retired") -> Experienced
A30: CUST1028 | B30: Joshua Ryan | C30: 27 | D30: Female | E30: New David | F30: New Jersey | G30: USA | H30: Platinum | M30: CUST1028 | N30: Joshua Ryan | O30: 27 | P30: Female | Q30: New David | R30: New Jersey | S30: USA | T30: Platinum | U30: =_xlfn.IFS(Table1__2[[#This Row],[Age]]<=19,"Teenage",Table1__2[[#This Row],[Age]]<=24,"Students",Table1__2[[#This Row],[Age]]<=30,"Entry level Professionel",Table1__2[[#This Row],[Age]]<=60,"Experienced",Table1__2[[#This Row],[Age]]>60,"Retired") -> Entry level Professionel
A31: CUST1029 | B31: David Arnold | C31: 54 | D31: Female | E31: East Jennifer | F31: California | G31: USA | H31: Silver | M31: CUST1029 | N31: David Arnold | O31: 54 | P31: Female | Q31: East Jennifer | R31: California | S31: USA | T31: Silver | U31: =_xlfn.IFS(Table1__2[[#This Row],[Age]]<=19,"Teenage",Table1__2[[#This Row],[Age]]<=24,"Students",Table1__2[[#This Row],[Age]]<=30,"Entry level Professionel",Table1__2[[#This Row],[Age]]<=60,"Experienced",Table1__2[[#This Row],[Age]]>60,"Retired") -> Experienced
A32: CUST1030 | B32: Jessica Acevedo | C32: 64 | D32: Female | E32: Amybury | F32: Pennsylvania | G32: USA | H32: Bronze | M32: CUST1030 | N32: Jessica Acevedo | O32: 64 | P32: Female | Q32: Amybury | R32: Pennsylvania | S32: USA | T32: Bronze | U32: =_xlfn.IFS(Table1__2[[#This Row],[Age]]<=19,"Teenage",Table1__2[[#This Row],[Age]]<=24,"Students",Table1__2[[#This Row],[Age]]<=30,"Entry level Professionel",Table1__2[[#This Row],[Age]]<=60,"Experienced",Table1__2[[#This Row],[Age]]>60,"Retired") -> Retired
A33: CUST1031 | B33: Sarah Vance | C33: 41 | D33: Male | E33: Johnsonville | F33: Oregon | G33: USA | H33: Silver | M33: CUST1031 | N33: Sarah Vance | O33: 41 | P33: Male | Q33: Johnsonville | R33: Oregon | S33: USA | T33: Silver | U33: =_xlfn.IFS(Table1__2[[#This Row],[Age]]<=19,"Teenage",Table1__2[[#This Row],[Age]]<=24,"Students",Table1__2[[#This Row],[Age]]<=30,"Entry level Professionel",Table1__2[[#This Row],[Age]]<=60,"Experienced",Table1__2[[#This Row],[Age]]>60,"Retired") -> Experienced
A34: CUST1032 | B34: Mike Jennings | C34: 48 | D34: Female | E34: Fostermouth | F34: Arizona | G34: USA | H34: Gold | M34: CUST1032 | N34: Mike Jennings | O34: 48 | P34: Female | Q34: Fostermouth | R34: Arizona | S34: USA | T34: Gold | U34: =_xlfn.IFS(Table1__2[[#This Row],[Age]]<=19,"Teenage",Table1__2[[#This Row],[Age]]<=24,"Students",Table1__2[[#This Row],[Age]]<=30,"Entry level Professionel",Table1__2[[#This Row],[Age]]<=60,"Experienced",Table1__2[[#This Row],[Age]]>60,"Retired") -> Experienced
A35: CUST1033 | B35: Robert Jones DDS | C35: 25 | D35: Male | E35: Tristanton | F35: Oklahoma | G35: USA | H35: Platinum | M35: CUST1033 | N35: Robert Jones Dds | O35: 25 | P35: Male | Q35: Tristanton | R35: Oklahoma | S35: USA | T35: Platinum | U35: =_xlfn.IFS(Table1__2[[#This Row],[Age]]<=19,"Teenage",Table1__2[[#This Row],[Age]]<=24,"Students",Table1__2[[#This Row],[Age]]<=30,"Entry level Professionel",Table1__2[[#This Row],[Age]]<=60,"Experienced",Table1__2[[#This Row],[Age]]>60,"Retired") -> Entry level Professionel
A36: CUST1034 | B36: Christopher Olson | C36: 27 | D36: Female | E36: West Richard | F36: Maryland | G36: USA | H36: Platinum | M36: CUST1034 | N36: Christopher Olson | O36: 27 | P36: Female | Q36: West Richard | R36: Maryland | S36: USA | T36: Platinum | U36: =_xlfn.IFS(Table1__2[[#This Row],[Age]]<=19,"Teenage",Table1__2[[#This Row],[Age]]<=24,"Students",Table1__2[[#This Row],[Age]]<=30,"Entry level Professionel",Table1__2[[#This Row],[Age]]<=60,"Experienced",Table1__2[[#This Row],[Age]]>60,"Retired") -> Entry level Professionel
A37: CUST1035 | B37: Rachel Myers | C37: 52 | D37: Male | E37: Robertberg | F37: North Dakota | G37: USA | H37: Silver | M37: CUST1035 | N37: Rachel Myers | O37: 52 | P37: Male | Q37: Robertberg | R37: North Dakota | S37: USA | T37: Silver | U37: =_xlfn.IFS(Table1__2[[#This Row],[Age]]<=19,"Teenage",Table1__2[[#This Row],[Age]]<=24,"Students",Table1__2[[#This Row],[Age]]<=30,"Entry level Professionel",Table1__2[[#This Row],[Age]]<=60,"Experienced",Table1__2[[#This Row],[Age]]>60,"Retired") -> Experienced
A38: CUST1036 | B38: Thomas Phillips | C38: 20 | D38: Female | E38: Luisfurt | F38: Georgia | G38: USA | H38: Gold | M38: CUST1036 | N38: Thomas Phillips | O38: 20 | P38: Female | Q38: Luisfurt | R38: Georgia | S38: USA | T38: Gold | U38: =_xlfn.IFS(Table1__2[[#This Row],[Age]]<=19,"Teenage",Table1__2[[#This Row],[Age]]<=24,"Students",Table1__2[[#This Row],[Age]]<=30,"Entry level Professionel",Table1__2[[#This Row],[Age]]<=60,"Experienced",Table1__2[[#This Row],[Age]]>60,"Retired") -> Students
A39: CUST1037 | B39: Christopher Carter | C39: 27 | D39: Female | E39: Brendastad | F39: South Dakota | G39: USA | M39: CUST1037 | N39: Christopher Carter | O39: 27 | P39: Female | Q39: Brendastad | R39: South Dakota | S39: USA | T39: unknown | U39: =_xlfn.IFS(Table1__2[[#This Row],[Age]]<=19,"Teenage",Table1__2[[#This Row],[Age]]<=24,"Students",Table1__2[[#This Row],[Age]]<=30,"Entry level Professionel",Table1__2[[#This Row],[Age]]<=60,"Experienced",Table1__2[[#This Row],[Age]]>60,"Retired") -> Entry level Professionel
A40: CUST1038 | B40: Deanna Simpson | C40: 35 | D40: Female | E40: Brownport | F40: North Dakota | G40: USA | H40: Bronze | M40: CUST1038 | N40: Deanna Simpson | O40: 35 | P40: Female | Q40: Brownport | R40: North Dakota | S40: USA | T40: Bronze | U40: =_xlfn.IFS(Table1__2[[#This Row],[Age]]<=19,"Teenage",Table1__2[[#This Row],[Age]]<=24,"Students",Table1__2[[#This Row],[Age]]<=30,"Entry level Professionel",Table1__2[[#This Row],[Age]]<=60,"Experienced",Table1__2[[#This Row],[Age]]>60,"Retired") -> Experienced
...

Sheet Product
A1: Product_ID | B1: Product_Name | C1: Category | D1: Sub_Category | E1: Brand | F1: Cost | G1: Stock | K1: Product_ID | L1: Product_Description | M1: Product_Type | N1: Category | O1: Sub_Category | P1: Brand | Q1: Cost | R1: Stock
A2: PROD0 | B2: Brother Laser Printer | C2: Electronics | D2: Computer | E2: Hunt Inc | F2: 112.42 | G2: 416 | K2: PROD0 | L2: Brother Laser | M2: Printer | N2: Electronics | O2: Computer | P2: Hunt Inc | Q2: 112.42 | R2: 416
A3: PROD1 | B3: Men's Graphic T-Shirt | C3: Clothing | D3: Tops | E3: Terry-Moore | F3: 342.56 | G3: 181 | K3: PROD1 | L3: Men's Graphic | M3: T-Shirt | N3: Clothing | O3: Tops | P3: Terry-Moore | Q3: 342.56 | R3: 181
A4: PROD2 | B4: Women's Casual Hoodie | C4: Clothing | D4: Outerwear | E4: Sims Inc | G4: 352 | K4: PROD2 | L4: Women's Casual | M4: Hoodie | N4: Clothing | O4: Outerwear | P4: Sims Inc | Q4: 254.04 | R4: 352
A5: P-3 | B5: Men's Running Jacket | C5: Clothing | D5: Outerwear | E5: Pineda Ltd | F5: 364.67 | G5: 452 | K5: PROD3 | L5: Men's Running | M5: Jacket | N5: Clothing | O5: Outerwear | P5: Pineda Ltd | Q5: 364.67 | R5: 452
A6: PROD4 | B6: Women's Yoga Pants | C6: Clothing | D6: Bottoms | E6: Gonzales-Davis | F6: 306.46 | G6: 487 | K6: PROD4 | L6: Women's Yoga | M6: Pants | N6: Clothing | O6: Bottoms | P6: Gonzales-Davis | Q6: 306.46 | R6: 487
A7: PROD5 | B7: Men's Leather Belt | C7: Clothing | D7: Accessories | E7: Baldwin, Garza and Gonzalez | F7: 261 | G7: 59 | K7: PROD5 | L7: Men's Leather | M7: Belt | N7: Clothing | O7: Accessories | P7: Baldwin, Garza and Gonzalez | Q7: 261 | R7: 59
A8: PROD6 | B8: Herbal Face Moisturizer | C8: Beauty | D8: Skincare | E8: Davidson PLC | F8: 312.8 | G8: 350 | K8: PROD6 | L8: Herbal Face | M8: Moisturizer | N8: Beauty | O8: Skincare | P8: Davidson PLC | Q8: 312.8 | R8: 350 | T8: Descriptive Statistics | U8: Cost | V8: Stock
A9: PROD7 | B9: LED Table Lamp | C9: Home | D9: Lighting | E9: Harrell LLC | F9: 218.86 | G9: 170 | K9: PROD7 | L9: LED Table | M9: Lamp | N9: Home | O9: Lighting | P9: Harrell LLC | Q9: 218.86 | R9: 170
A10: PROD8 | B10: Wireless Bluetooth Earbuds | C10: Electronics | D10: Audio | E10: Perez-Johnston | F10: 439.07 | G10: 142 | K10: PROD8 | L10: Wireless Bluetooth | M10: Earbuds | N10: Electronics | O10: Audio | P10: Perez-Johnston | Q10: 439.07 | R10: 142 | T10: Mean | U10: 254.0434 | V10: 273.48
A11: PROD9 | B11: Adjustable Dumbbell Set | C11: Sports | D11: Fitness | E11: Hill PLC | F11: 495.72 | G11: 323 | K11: PROD9 | L11: Adjustable Dumbbell | M11: Set | N11: Sports | O11: Fitness | P11: Hill PLC | Q11: 495.72 | R11: 323 | T11: Standard Error | U11: 13.082031 | V11: 12.995046
A12: PROD10 | B12: Ceramic Kitchen Bowl Set | C12: Home | D12: Kitchen | E12: Hamilton Group | F12: 298.86 | G12: 308 | K12: PROD10 | L12: Ceramic Kitchen Bowl | M12: Set | N12: Home | O12: Kitchen | P12: Hamilton Group | Q12: 298.86 | R12: 308 | T12: Median | U12: 253.685 | V12: 273
A13: PROD11 | B13: HD Smart TV Stick | C13: Electronics | D13: Accessories | E13: Gibson, Hobbs and Weaver | F13: 449.4 | K13: PROD11 | L13: HD Smart TV | M13: Stick | N13: Electronics | O13: Accessories | P13: Gibson, Hobbs and Weaver | Q13: 449.4 | R13: 273 | T13: Mode | U13: 254.04 | V13: 273
A14: PROD12 | B14: Hair Strengthening Shampoo | C14: Beauty | D14: Haircare | E14: Rice LLC | F14: 115.82 | G14: 460 | K14: PROD12 | L14: Hair Strengthening | M14: Shampoo | N14: Beauty | O14: Haircare | P14: Rice LLC | Q14: 115.82 | R14: 460 | T14: Standard Deviation | U14: 130.82031 | V14: 129.95046
A15: PROD13 | B15: USB-C Fast Charger | C15: Electronics | D15: Accessories | E15: Dawson-Perkins | F15: 242.23 | G15: 453 | K15: PROD13 | L15: USB-C Fast | M15: Charger | N15: Electronics | O15: Accessories | P15: Dawson-Perkins | Q15: 242.23 | R15: 453 | T15: Sample Variance | U15: 17113.953 | V15: 16887.121
A16: PROD14 | B16: Decorative Wall Mirror | C16: Home | D16: Decor | E16: Luna, Anderson and Bowman | F16: 48.01 | G16: 439 | K16: PROD14 | L16: Decorative Wall | M16: Mirror | N16: Home | O16: Decor | P16: Luna, Anderson and Bowman | Q16: 48.01 | R16: 439 | T16: Kurtosis | U16: -0.94910609 | V16: -1.1529465
A17: PROD15 | B17: 4K Home Projector | C17: Electronics | D17: Appliances | E17: Thomas LLC | F17: 465.34 | G17: 301 | K17: PROD15 | L17: 4K Home | M17: Projector | N17: Electronics | O17: Appliances | P17: Thomas LLC | Q17: 465.34 | R17: 301 | T17: Skewness | U17: 0.052323422 | V17: -0.0073416277
A18: P-16 | B18: Beard Grooming Kit | C18: Beauty | D18: Grooming | E18: Erickson-Green | F18: 337.42 | G18: 256 | K18: PROD16 | L18: Beard Grooming | M18: Kit | N18: Beauty | O18: Grooming | P18: Erickson-Green | Q18: 337.42 | R18: 256 | T18: Range | U18: 478.41 | V18: 439
A19: PROD17 | B19: Soccer Training Cone Set | C19: Sports | D19: Accessories | E19: Ford, Murphy and Wilson | F19: 144.53 | G19: 367 | K19: PROD17 | L19: Soccer Training Cone | M19: Set | N19: Sports | O19: Accessories | P19: Ford, Murphy and Wilson | Q19: 144.53 | R19: 367 | T19: Minimum | U19: 17.31 | V19: 57
A20: PROD18 | B20: Women's Denim Jeans | C20: Clothing | D20: Bottoms | E20: Guerra-Hendrix | G20: 343 | K20: PROD18 | L20: Women's Denim | M20: Jeans | N20: Clothing | O20: Bottoms | P20: Guerra-Hendrix | Q20: 254.04 | R20: 343 | T20: Maximum | U20: 495.72 | V20: 496
A21: PROD19 | B21: Knee Support Brace | C21: Sports | D21: Equipment | E21: May-Reese | F21: 21.34 | G21: 65 | K21: PROD19 | L21: Knee Support | M21: Brace | N21: Sports | O21: Equipment | P21: May-Reese | Q21: 21.34 | R21: 65 | T21: Sum | U21: 25404.34 | V21: 27348
A22: PROD20 | B22: Outdoor Sports Water Bottle | C22: Sports | D22: Accessories | E22: Soto-Ellis | F22: 131.51 | K22: PROD20 | L22: Outdoor Sports Water | M22: Bottle | N22: Sports | O22: Accessories | P22: Soto-Ellis | Q22: 131.51 | R22: 273 | T22: Count | U22: 100 | V22: 100
A23: PROD21 | B23: Multi-Purpose Storage Box | C23: Home | D23: Storage | E23: Gardner-Montes | F23: 123.46 | G23: 76 | K23: PROD21 | L23: Multi-Purpose Storage | M23: Box | N23: Home | O23: Storage | P23: Gardner-Montes | Q23: 123.46 | R23: 76
A24: PROD22 | B24: Carbon Fiber Tennis Racket | C24: Sports | D24: Equipment | E24: Flores, Pineda and Rodriguez | F24: 484.62 | G24: 432 | K24: PROD22 | L24: Carbon Fiber Tennis | M24: Racket | N24: Sports | O24: Equipment | P24: Flores, Pineda and Rodriguez | Q24: 484.62 | R24: 432
A25: PROD23 | B25: Men's Formal Shirt | C25: Clothing | D25: Tops | E25: Moon, Mora and Santos | G25: 360 | K25: PROD23 | L25: Men's Formal | M25: Shirt | N25: Clothing | O25: Tops | P25: Moon, Mora and Santos | Q25: 254.04 | R25: 360
A26: PROD24 | B26: Foldable Camping Chair | C26: Sports | D26: Outdoor | E26: Cook Ltd | F26: 166.06 | G26: 340 | K26: PROD24 | L26: Foldable Camping | M26: Chair | N26: Sports | O26: Outdoor | P26: Cook Ltd | Q26: 166.06 | R26: 340
A27: PROD25 | B27: Women's Scarf Set | C27: Clothing | D27: Accessories | E27: Brown and Sons | F27: 174.02 | G27: 268 | K27: PROD25 | L27: Women's Scarf | M27: Set | N27: Clothing | O27: Accessories | P27: Brown and Sons | Q27: 174.02 | R27: 268
A28: PROD26 | B28: Wireless Bluetooth Speaker | C28: Electronics | D28: Audio | E28: Reed-Schmidt | F28: 322.41 | G28: 213 | K28: PROD26 | L28: Wireless Bluetooth | M28: Speaker | N28: Electronics | O28: Audio | P28: Reed-Schmidt | Q28: 322.41 | R28: 213
A29: PROD27 | B29: Decorative Floor Vase | C29: Home | D29: Decor | E29: Khan, Jones and Paul | G29: 378 | K29: PROD27 | L29: Decorative Floor | M29: Vase | N29: Home | O29: Decor | P29: Khan, Jones and Paul | Q29: 254.04 | R29: 378
A30: PROD28 | B30: Sports Stopwatch Timer | C30: Sports | D30: Accessories | E30: Burns-Hansen | F30: 38.76 | G30: 137 | K30: PROD28 | L30: Sports Stopwatch | M30: Timer | N30: Sports | O30: Accessories | P30: Burns-Hansen | Q30: 38.76 | R30: 137
A31: PROD29 | B31: Fabric Sofa Throw Blanket | C31: Home | D31: Decor | E31: Hoffman Group | F31: 218.48 | G31: 276 | K31: PROD29 | L31: Fabric Sofa Throw | M31: Blanket | N31: Home | O31: Decor | P31: Hoffman Group | Q31: 218.48 | R31: 276
A32: PROD30 | B32: Stainless Steel Cutlery Set | C32: Home | D32: Kitchen | E32: Stevens, Fernandez and Martin | F32: 19.52 | G32: 57 | K32: PROD30 | L32: Stainless Steel Cutlery | M32: Set | N32: Home | O32: Kitchen | P32: Stevens, Fernandez and Martin | Q32: 19.52 | R32: 57
A33: PROD31 | B33: Basketball | C33: Sports | D33: Team Sports | E33: Nolan-Snow | F33: 204.39 | G33: 281 | K33: PROD31 | L33: Basketball | M33: Ball | N33: Sports | O33: Team Sports | P33: Nolan-Snow | Q33: 204.39 | R33: 281
A34: PROD32 | B34: Vitamin C Face Serum | C34: Beauty | D34: Skincare | E34: Griffin Ltd | F34: 283.83 | G34: 244 | K34: PROD32 | L34: Vitamin C Face | M34: Serum | N34: Beauty | O34: Skincare | P34: Griffin Ltd | Q34: 283.83 | R34: 244
A35: PROD33 | B35: Modern Wall Clock | C35: Home | D35: Decor | E35: Weiss-Watson | F35: 179.77 | G35: 305 | K35: PROD33 | L35: Modern Wall | M35: Clock | N35: Home | O35: Decor | P35: Weiss-Watson | Q35: 179.77 | R35: 305
A36: PROD34 | B36: Gaming Mechanical Keyboard | C36: Electronics | D36: Computer | E36: Lucero LLC | F36: 419.28 | G36: 86 | K36: PROD34 | L36: Gaming Mechanical | M36: Keyboard | N36: Electronics | O36: Computer | P36: Lucero LLC | Q36: 419.28 | R36: 86
A37: PROD35 | B37: Bedroom Table Lamp | C37: Home | D37: Lighting | E37: Jones LLC | F37: 382.22 | G37: 329 | K37: PROD35 | L37: Bedroom Table | M37: Lamp | N37: Home | O37: Lighting | P37: Jones LLC | Q37: 382.22 | R37: 329
A38: PROD36 | B38: Women's Summer Dress | C38: Clothing | D38: Tops | E38: Smith-Mills | F38: 223.43 | G38: 154 | K38: PROD36 | L38: Women's Summer | M38: Dress | N38: Clothing | O38: Tops | P38: Smith-Mills | Q38: 223.43 | R38: 154
A39: PROD37 | B39: Men's Casual Sneakers | C39: Clothing | D39: Footwear | E39: Hogan-Lee | F39: 353.47 | G39: 214 | K39: PROD37 | L39: Men's Casual | M39: Sneakers | N39: Clothing | O39: Footwear | P39: Hogan-Lee | Q39: 353.47 | R39: 214
A40: PROD38 | B40: Sports Water Hydration Pack | C40: Sports | D40: Outdoor | E40: Sims-Smith | F40: 135.61 | G40: 394 | K40: PROD38 | L40: Sports Water Hydration | M40: Pack | N40: Sports | O40: Outdoor | P40: Sims-Smith | Q40: 135.61 | R40: 394
...

Sheet Store
A1: Store_ID | B1: Store_Name | C1: Region | D1: City | E1: Store_Type | F1: Store Category
A2: STORE0 | B2: Rivera-Warner | C2: East | D2: Washingtonfurt | E2: Flagship | F2: =IF(Table7[[#This Row],[Store_Type]]="Online","Digital Store","Physical Store") -> Physical Store
A3: STORE1 | B3: Martinez, Adkins and Johnson | C3: North | D3: Danielmouth | E3: Flagship | F3: =IF(Table7[[#This Row],[Store_Type]]="Online","Digital Store","Physical Store") -> Physical Store
A4: STORE2 | B4: Black-Horn | C4: South | D4: North Nancyview | E4: Outlet | F4: =IF(Table7[[#This Row],[Store_Type]]="Online","Digital Store","Physical Store") -> Physical Store
A5: STORE3 | B5: Johnson-Wright | C5: North | D5: Hoodberg | E5: Outlet | F5: =IF(Table7[[#This Row],[Store_Type]]="Online","Digital Store","Physical Store") -> Physical Store
A6: STORE4 | B6: Alexander Group | C6: South | D6: Port Sharon | E6: Online | F6: =IF(Table7[[#This Row],[Store_Type]]="Online","Digital Store","Physical Store") -> Digital Store
A7: STORE5 | B7: Gray Ltd | C7: North | D7: New Michaelchester | E7: Outlet | F7: =IF(Table7[[#This Row],[Store_Type]]="Online","Digital Store","Physical Store") -> Physical Store
A8: STORE6 | B8: Benson-Elliott | C8: East | D8: Port Josephberg | E8: Online | F8: =IF(Table7[[#This Row],[Store_Type]]="Online","Digital Store","Physical Store") -> Digital Store
A9: STORE7 | B9: Martinez-Mullins | C9: South | D9: Williamsfurt | E9: Online | F9: =IF(Table7[[#This Row],[Store_Type]]="Online","Digital Store","Physical Store") -> Digital Store
A10: STORE8 | B10: Bean, Jones and Park | C10: West | D10: Thompsonborough | E10: Online | F10: =IF(Table7[[#This Row],[Store_Type]]="Online","Digital Store","Physical Store") -> Digital Store
A11: STORE9 | B11: Moore, Padilla and Butler | C11: South | D11: East Johnstad | E11: Flagship | F11: =IF(Table7[[#This Row],[Store_Type]]="Online","Digital Store","Physical Store") -> Physical Store
A12: STORE10 | B12: Hill, Wagner and Ballard | C12: East | D12: East Davidville | E12: Online | F12: =IF(Table7[[#This Row],[Store_Type]]="Online","Digital Store","Physical Store") -> Digital Store
A13: STORE11 | B13: Aguirre-Keller | C13: South | D13: Lake Michael | E13: Online | F13: =IF(Table7[[#This Row],[Store_Type]]="Online","Digital Store","Physical Store") -> Digital Store
... A21: STORE19 | B21: Mann-Austin | C21: East | D21: Vasquezborough | E21: Online | F21: =IF(Table7[[#This Row],[Store_Type]]="Online","Digital Store","Physical Store") -> Digital Store

Sheet Sales
A1: Sales_ID | B1: Order_Date | C1: Customer_ID | D1: Product_ID | E1: Store_ID | F1: Quantity | G1: Unit_Price | H1: Discount | I1: Payment_Type | J1: Total_Amount | O1: Sales_ID | P1: Order_Date | Q1: Customer_ID | R1: Product_ID | S1: Store_ID | T1: Quantity | U1: Unit_Price | V1: Discount | W1: Payment_Type | X1: Total_Amount | Y1: Amount_Paid | Z1: Price Range
A2: SALE0 | B2: 45480 | C2: CUST1409 | D2: PROD97 | E2: STORE3 | F2: 1 | G2: 218.04 | H2: 0.09 | I2: Credit Card | J2: 198.4164 | O2: SALE0 | P2: 45480 | Q2: CUST1409 | R2: PROD97 | S2: STORE3 | T2: 1 | U2: 218.04 | V2: 0.09 | W2: Credit Card | X2: 198.4164 | Y2: 198.4164 | Z2: =_xlfn.IFS(Table8_1[[#This Row],[Unit_Price]]<500,"Low Price",Table8_1[[#This Row],[Unit_Price]]<2000,"Medium Price",Table8_1[[#This Row],[Unit_Price]]>=2000, "High Price") -> Low Price
A3: SALE1 | B3: 45285 | C3: CUST1467 | D3: PROD74 | E3: STORE17 | F3: 3 | G3: 104.47 | H3: 0.27 | I3: PayPal | J3: 228.7893 | O3: SALE1 | P3: 45285 | Q3: CUST1467 | R3: PROD74 | S3: STORE17 | T3: 3 | U3: 104.47 | V3: 0.27 | W3: PayPal | X3: 228.7893 | Y3: 228.7893 | Z3: =_xlfn.IFS(Table8_1[[#This Row],[Unit_Price]]<500,"Low Price",Table8_1[[#This Row],[Unit_Price]]<2000,"Medium Price",Table8_1[[#This Row],[Unit_Price]]>=2000, "High Price") -> Low Price
A4: SALE2 | B4: 45446 | C4: CUST1056 | D4: PROD49 | E4: STORE8 | F4: 4 | G4: 914.05 | H4: 0.25 | I4: Credit Card | J4: 2742.15 | O4: SALE2 | P4: 45446 | Q4: CUST1056 | R4: PROD49 | S4: STORE8 | T4: 4 | U4: 914.05 | V4: 0.25 | W4: Credit Card | X4: 2742.15 | Y4: 2742.15 | Z4: =_xlfn.IFS(Table8_1[[#This Row],[Unit_Price]]<500,"Low Price",Table8_1[[#This Row],[Unit_Price]]<2000,"Medium Price",Table8_1[[#This Row],[Unit_Price]]>=2000, "High Price") -> Medium Price
A5: SALE3 | B5: 45259 | C5: CUST1346 | D5: PROD76 | E5: STORE8 | F5: 1 | G5: 921.51 | H5: 0.16 | I5: COD | J5: 774.0684 | O5: SALE3 | P5: 45259 | Q5: CUST1346 | R5: PROD76 | S5: STORE8 | T5: 1 | U5: 921.51 | V5: 0.16 | W5: COD | X5: 774.0684 | Y5: 774.0684 | Z5: =_xlfn.IFS(Table8_1[[#This Row],[Unit_Price]]<500,"Low Price",Table8_1[[#This Row],[Unit_Price]]<2000,"Medium Price",Table8_1[[#This Row],[Unit_Price]]>=2000, "High Price") -> Medium Price
A6: SALE4 | B6: 45297 | C6: CUST1493 | D6: PROD59 | E6: STORE5 | F6: 3 | G6: 745.3 | H6: 0.18 | I6: Credit Card | J6: 1833.438 | O6: SALE4 | P6: 45297 | Q6: CUST1493 | R6: PROD59 | S6: STORE5 | T6: 3 | U6: 745.3 | V6: 0.18 | W6: Credit Card | X6: 1833.438 | Y6: 1833.438 | Z6: =_xlfn.IFS(Table8_1[[#This Row],[Unit_Price]]<500,"Low Price",Table8_1[[#This Row],[Unit_Price]]<2000,"Medium Price",Table8_1[[#This Row],[Unit_Price]]>=2000, "High Price") -> Medium Price | AB6: Descriptive Statistics | AC6: Unit Price | AD6: Amount_Paid
A7: SALE5 | B7: 45499 | C7: CUST1116 | D7: PROD15 | E7: STORE7 | F7: 3 | G7: 147.01 | H7: 0.19 | I7: COD | J7: 357.2343 | O7: SALE5 | P7: 45499 | Q7: CUST1116 | R7: PROD15 | S7: STORE7 | T7: 3 | U7: 147.01 | V7: 0.19 | W7: COD | X7: 357.2343 | Y7: 357.2343 | Z7: =_xlfn.IFS(Table8_1[[#This Row],[Unit_Price]]<500,"Low Price",Table8_1[[#This Row],[Unit_Price]]<2000,"Medium Price",Table8_1[[#This Row],[Unit_Price]]>=2000, "High Price") -> Low Price
A8: SALE6 | B8: 45850 | C8: CUST1016 | D8: PROD56 | E8: STORE4 | F8: 2 | G8: 785.31 | H8: 0.15 | I8: PayPal | J8: 1335.027 | O8: SALE6 | P8: 45850 | Q8: CUST1016 | R8: PROD56 | S8: STORE4 | T8: 2 | U8: 785.31 | V8: 0.15 | W8: PayPal | X8: 1335.027 | Y8: 1335.027 | Z8: =_xlfn.IFS(Table8_1[[#This Row],[Unit_Price]]<500,"Low Price",Table8_1[[#This Row],[Unit_Price]]<2000,"Medium Price",Table8_1[[#This Row],[Unit_Price]]>=2000, "High Price") -> Medium Price | AB8: Mean | AC8: 513.98476 | AD8: 1086.5655
A9: SALE7 | B9: 45248 | C9: CUST1152 | D9: PROD70 | E9: STORE8 | F9: 4 | G9: 342.39 | H9: 0.23 | I9: PayPal | J9: 1054.5612 | O9: SALE7 | P9: 45248 | Q9: CUST1152 | R9: PROD70 | S9: STORE8 | T9: 4 | U9: 342.39 | V9: 0.23 | W9: PayPal | X9: 1054.5612 | Y9: 1054.5612 | Z9: =_xlfn.IFS(Table8_1[[#This Row],[Unit_Price]]<500,"Low Price",Table8_1[[#This Row],[Unit_Price]]<2000,"Medium Price",Table8_1[[#This Row],[Unit_Price]]>=2000, "High Price") -> Low Price | AB9: Standard Error | AC9: 6.3077953 | AD9: 18.301042
A10: SALE8 | B10: 45781 | C10: CUST1187 | D10: PROD99 | E10: STORE5 | G10: 448.25 | H10: 0.07 | I10: PayPal | J10: 1250.6175 | O10: SALE8 | P10: 45781 | Q10: CUST1187 | R10: PROD99 | S10: STORE5 | T10: 2 | U10: 448.25 | V10: 0.07 | W10: PayPal | X10: 1250.6175 | Y10: 833.745 | Z10: =_xlfn.IFS(Table8_1[[#This Row],[Unit_Price]]<500,"Low Price",Table8_1[[#This Row],[Unit_Price]]<2000,"Medium Price",Table8_1[[#This Row],[Unit_Price]]>=2000, "High Price") -> Low Price | AB10: Median | AC10: 522.43 | AD10: 868.7182
A11: SALE9 | B11: 45869 | C11: CUST1464 | D11: PROD33 | E11: STORE0 | F11: 2 | G11: 873.17 | H11: 0.23 | I11: PayPal | J11: 1344.6818 | O11: SALE9 | P11: 45869 | Q11: CUST1464 | R11: PROD33 | S11: STORE0 | T11: 2 | U11: 873.17 | V11: 0.23 | W11: PayPal | X11: 1344.6818 | Y11: 1344.6818 | Z11: =_xlfn.IFS(Table8_1[[#This Row],[Unit_Price]]<500,"Low Price",Table8_1[[#This Row],[Unit_Price]]<2000,"Medium Price",Table8_1[[#This Row],[Unit_Price]]>=2000, "High Price") -> Medium Price | AB11: Mode | AC11: 513.98 | AD11: #N/A
A12: SALE10 | B12: 45335 | C12: CUST1065 | D12: PROD24 | E12: STORE14 | F12: 1 | G12: 278.63 | H12: 0.07 | I12: Credit Card | J12: 259.1259 | O12: SALE10 | P12: 45335 | Q12: CUST1065 | R12: PROD24 | S12: STORE14 | T12: 1 | U12: 278.63 | V12: 0.07 | W12: Credit Card | X12: 259.1259 | Y12: 259.1259 | Z12: =_xlfn.IFS(Table8_1[[#This Row],[Unit_Price]]<500,"Low Price",Table8_1[[#This Row],[Unit_Price]]<2000,"Medium Price",Table8_1[[#This Row],[Unit_Price]]>=2000, "High Price") -> Low Price | AB12: Standard Deviation | AC12: 282.09318 | AD12: 818.4475
A13: SALE11 | B13: 45801 | C13: CUST1320 | D13: PROD39 | E13: STORE1 | F13: 4 | G13: 286.92 | H13: 0.17 | I13: Credit Card | J13: 952.5744 | O13: SALE11 | P13: 45801 | Q13: CUST1320 | R13: PROD39 | S13: STORE1 | T13: 4 | U13: 286.92 | V13: 0.17 | W13: Credit Card | X13: 952.5744 | Y13: 952.5744 | Z13: =_xlfn.IFS(Table8_1[[#This Row],[Unit_Price]]<500,"Low Price",Table8_1[[#This Row],[Unit_Price]]<2000,"Medium Price",Table8_1[[#This Row],[Unit_Price]]>=2000, "High Price") -> Low Price | AB13: Sample Variance | AC13: 79576.564 | AD13: 669856.3
A14: SALE12 | B14: 45528 | C14: CUST1237 | D14: PROD88 | E14: STORE4 | F14: 4 | G14: 644.58 | H14: 0.01 | I14: Credit Card | J14: 2552.5368 | O14: SALE12 | P14: 45528 | Q14: CUST1237 | R14: PROD88 | S14: STORE4 | T14: 4 | U14: 644.58 | V14: 0.01 | W14: Credit Card | X14: 2552.5368 | Y14: 2552.5368 | Z14: =_xlfn.IFS(Table8_1[[#This Row],[Unit_Price]]<500,"Low Price",Table8_1[[#This Row],[Unit_Price]]<2000,"Medium Price",Table8_1[[#This Row],[Unit_Price]]>=2000, "High Price") -> Medium Price | AB14: Kurtosis | AC14: -1.1897064 | AD14: 0.059308206
A15: SALE13 | B15: 45875 | C15: CUST1443 | D15: PROD34 | E15: STORE16 | F15: 2 | G15: 316.9 | H15: 0.3 | I15: PayPal | J15: 443.66 | O15: SALE13 | P15: 45875 | Q15: CUST1443 | R15: PROD34 | S15: STORE16 | T15: 2 | U15: 316.9 | V15: 0.3 | W15: PayPal | X15: 443.66 | Y15: 443.66 | Z15: =_xlfn.IFS(Table8_1[[#This Row],[Unit_Price]]<500,"Low Price",Table8_1[[#This Row],[Unit_Price]]<2000,"Medium Price",Table8_1[[#This Row],[Unit_Price]]>=2000, "High Price") -> Low Price | AB15: Skewness | AC15: -0.036768714 | AD15: 0.88189426
A16: SALE14 | B16: 45829 | C16: CUST1348 | D16: PROD24 | E16: STORE15 | F16: 4 | G16: 403.47 | H16: 0.29 | I16: PayPal | J16: 1145.8548 | O16: SALE14 | P16: 45829 | Q16: CUST1348 | R16: PROD24 | S16: STORE15 | T16: 4 | U16: 403.47 | V16: 0.29 | W16: PayPal | X16: 1145.8548 | Y16: 1145.8548 | Z16: =_xlfn.IFS(Table8_1[[#This Row],[Unit_Price]]<500,"Low Price",Table8_1[[#This Row],[Unit_Price]]<2000,"Medium Price",Table8_1[[#This Row],[Unit_Price]]>=2000, "High Price") -> Low Price | AB16: Range | AC16: 979.8 | AD16: 3889.7838
A17: SALE15 | B17: 45636 | C17: CUST1435 | D17: PROD36 | E17: STORE9 | G17: 871.34 | H17: 0.04 | I17: COD | J17: 2509.4592 | O17: SALE15 | P17: 45636 | Q17: CUST1435 | R17: PROD36 | S17: STORE9 | T17: 2 | U17: 871.34 | V17: 0.04 | W17: COD | X17: 2509.4592 | Y17: 1672.9728 | Z17: =_xlfn.IFS(Table8_1[[#This Row],[Unit_Price]]<500,"Low Price",Table8_1[[#This Row],[Unit_Price]]<2000,"Medium Price",Table8_1[[#This Row],[Unit_Price]]>=2000, "High Price") -> Medium Price | AB17: Minimum | AC17: 20.09 | AD17: 18.459
A18: SALE16 | B18: 45913 | C18: CUST1276 | D18: PROD65 | E18: STORE19 | F18: 2 | G18: 451.98 | H18: 0.25 | I18: Credit Card | J18: 677.97 | O18: SALE16 | P18: 45913 | Q18: CUST1276 | R18: PROD65 | S18: STORE19 | T18: 2 | U18: 451.98 | V18: 0.25 | W18: Credit Card | X18: 677.97 | Y18: 677.97 | Z18: =_xlfn.IFS(Table8_1[[#This Row],[Unit_Price]]<500,"Low Price",Table8_1[[#This Row],[Unit_Price]]<2000,"Medium Price",Table8_1[[#This Row],[Unit_Price]]>=2000, "High Price") -> Low Price | AB18: Maximum | AC18: 999.89 | AD18: 3908.2428
